2024-01-11 15:01:56,366 ERROR Internal Server Error: /news/test_error /Users/sky/PycharmProjects/DjangoProject/venv/lib/python3.9/site-packages/django/utils/log.py (<class 'Exception'>, Exception(), <traceback object at 0x10c4951c0>)
Traceback (most recent call last):
  File "/Users/sky/PycharmProjects/DjangoProject/venv/lib/python3.9/site-packages/django/core/handlers/exception.py", line 47, in inner
    response = get_response(request)
  File "/Users/sky/PycharmProjects/DjangoProject/venv/lib/python3.9/site-packages/django/core/handlers/base.py", line 181, in _get_response
    response = wrapped_callback(request, *callback_args, **callback_kwargs)
  File "/Users/sky/PycharmProjects/DjangoProject/SkillFactory_D7-/main_app/views.py", line 176, in test_error
    raise Exception
Exception
2024-01-11 15:01:57,754 ERROR "GET /news/test_error HTTP/1.1" 500 145 /Users/sky/PycharmProjects/DjangoProject/venv/lib/python3.9/site-packages/django/core/servers/basehttp.py None
2024-01-11 19:43:48,619 ERROR Internal Server Error: /news/test_error /Users/sky/PycharmProjects/DjangoProject/venv/lib/python3.9/site-packages/django/utils/log.py (<class 'Exception'>, Exception(), <traceback object at 0x1078740c0>)
Traceback (most recent call last):
  File "/Users/sky/PycharmProjects/DjangoProject/venv/lib/python3.9/site-packages/django/core/handlers/exception.py", line 47, in inner
    response = get_response(request)
  File "/Users/sky/PycharmProjects/DjangoProject/venv/lib/python3.9/site-packages/django/core/handlers/base.py", line 181, in _get_response
    response = wrapped_callback(request, *callback_args, **callback_kwargs
  File "/Users/sky/PycharmProjects/DjangoProject/SkillFactory_D7/main_app/views.py", line 176, in test_error
    raise Exception
Exception
2024-01-11 19:43:50,435 ERROR "GET /news/test_error HTTP/1.1" 500 145 /Users/sky/PycharmProjects/DjangoProject/venv/lib/python3.9/site-packages/django/core/servers/basehttp.py None
2024-01-11 19:43:52,872 ERROR Internal Server Error: /news/test_error /Users/sky/PycharmProjects/DjangoProject/venv/lib/python3.9/site-packages/django/utils/log.py (<class 'Exception'>, Exception(), <traceback object at 0x1077ccec0>)
Traceback (most recent call last):
  File "/Users/sky/PycharmProjects/DjangoProject/venv/lib/python3.9/site-packages/django/core/handlers/exception.py", line 47, in inner
    response = get_response(request)
  File "/Users/sky/PycharmProjects/DjangoProject/venv/lib/python3.9/site-packages/django/core/handlers/base.py", line 181, in _get_response
    response = wrapped_callback(request, *callback_args, **callback_kwargs)
  File "/Users/sky/PycharmProjects/DjangoProject/SkillFactory_D7/main_app/views.py", line 176, in test_error
    raise Exception
Exception
2024-01-11 19:43:53,816 ERROR "GET /news/test_error HTTP/1.1" 500 145 /Users/sky/PycharmProjects/DjangoProject/venv/lib/python3.9/site-packages/django/core/servers/basehttp.py None
2024-02-10 12:42:42,575 ERROR Internal Server Error: /news/test_error C:\Users\aeras\PycharmProjects\DjangoProject\venv\lib\site-packages\django\utils\log.py (<class 'Exception'>, Exception(), <traceback object at 0x000001172D383EC0>)
Traceback (most recent call last):
  File "C:\Users\aeras\PycharmProjects\DjangoProject\venv\lib\site-packages\django\core\handlers\exception.py", line 55, in inner
    response = get_response(request)
  File "C:\Users\aeras\PycharmProjects\DjangoProject\venv\lib\site-packages\django\core\handlers\base.py", line 197, in _get_response
    response = wrapped_callback(request, *callback_args, **callback_kwargs)
  File "C:\Users\aeras\PycharmProjects\DjangoProject\SkillFactory_D13\main_app\views.py", line 155, in test_error
    raise Exception
Exception
2024-02-10 12:42:42,577 ERROR "GET /news/test_error HTTP/1.1" 500 73358 C:\Users\aeras\PycharmProjects\DjangoProject\venv\lib\site-packages\django\core\servers\basehttp.py None
